fn main() {
  panic!( "This exception is expected." )
}
